<mujoco model="threedof">
  <option iterations="50" timestep="0.001" solver="PGS" gravity="0 0 -9.81" />
  <compiler angle="radian" meshdir="meshes" eulerseq="zyx" autolimits="true" />

  <default>
    <joint limited="true" damping="0.01" armature="0.01" frictionloss="0.01" />
    <geom condim="4" contype="1" conaffinity="15" friction="0.9 0.2 0.2" solref="0.001 2" />
    <motor ctrllimited="true" />
    <equality solref="0.001 2" />
    <default class="visualgeom">
      <geom material="visualgeom" condim="1" contype="0" conaffinity="0" />
    </default>
  </default>

  <asset>
    <mesh name="backarm" file="backarm.stl" scale="0.002 0.002 0.002" />
    <mesh name="forearm" file="forearm.stl" scale="0.002 0.002 0.002" />
    <mesh name="indo0" file="indo0.stl" scale="0.002 0.002 0.002" />
    <mesh name="ind1" file="ind1.stl" scale="0.002 0.002 0.002" />
    <mesh name="ind2" file="ind2.stl" scale="0.002 0.002 0.002" />
    <mesh name="mid0" file="mid0.stl" scale="0.002 0.002 0.002" />
    <mesh name="mid1" file="mid1.stl" scale="0.002 0.002 0.002" />
    <mesh name="mid2" file="mid2.stl" scale="0.002 0.002 0.002" />
    <mesh name="palm" file="palm.stl" scale="0.002 0.002 0.002" />
    <mesh name="pink0" file="pink0.stl" scale="0.002 0.002 0.002" />
    <mesh name="pink1" file="pink1.stl" scale="0.002 0.002 0.002" />
    <mesh name="pink2" file="pink2.stl" scale="0.002 0.002 0.002" />
    <mesh name="ring0" file="ring0.stl" scale="0.002 0.002 0.002" />
    <mesh name="ring1" file="ring1.stl" scale="0.002 0.002 0.002" />
    <mesh name="ring2" file="ring2.stl" scale="0.002 0.002 0.002" />
    <mesh name="thumb_joint" file="thumb_joint.stl" scale="0.002 0.002 0.002" />
    <mesh name="thumb0" file="thumb0.stl" scale="0.002 0.002 0.002" />
    <mesh name="thumb1" file="thumb1.stl" scale="0.002 0.002 0.002" />
    <mesh name="thumb2" file="thumb2.stl" scale="0.002 0.002 0.002" />
    <texture name="texplane" type="2d" builtin="checker" rgb1=".0 .0 .0" rgb2=".8 .8 .8" width="100" height="100" />
    <material name="matplane" reflectance="0." texture="texplane" texrepeat="1 1" texuniform="true" />
    <material name="visualgeom" rgba="0.5 0.9 0.2 1" />
  </asset>

  <worldbody>
    <light directional="true" diffuse="0.4 0.4 0.4" specular="0.1 0.1 0.1" pos="0 0 5.0" dir="0 0 -1" castshadow="false" />
    <light directional="true" diffuse="0.6 0.6 0.6" specular="0.2 0.2 0.2" pos="0 0 4" dir="0 0 -1" />
    <geom name="ground" type="plane" pos="0 0 0" size="100 100 0.001" quat="1 0 0 0" material="matplane" condim="3" conaffinity="15" />
    <camera name="fixed" pos="0 -3.0 0.5025604315112503" xyaxes="1 0 0 0 0 1" />
    <camera name="track" mode="trackcom" pos="0 -3.0 0.5025604315112503" xyaxes="1 0 0 0 0 1" />
    <body name="root" pos="0 0 0.002560431511250294" quat="1 0 0 0">
      <inertial pos="0 0 0" quat="0.471858 -0.00115011 0.00061552 0.881674" mass="0.5" diaginertia="0.0150001 0.015 0.00117991" />
      <joint name="root_joint" pos="0 0 0" axis="-1 0 0" range="-0.001 0.001" damping="10" stiffness="200" />
      <site name="imu" size="0.01" pos="0 0 0" />
      <body name="backarm_link">
        <inertial pos="0 0 0" quat="0.471858 -0.00115011 0.00061552 0.881674" mass="0.5" diaginertia="0.0150001 0.015 0.00117991" />
        <joint name="backarmx_link_joint" pos="0 0 0" axis="-1 0 0" range="-3.14 3.14" damping="10" stiffness="200" />
        <body name="backarm_link.001">
          <inertial pos="0 0 0" quat="0.471858 -0.00115011 0.00061552 0.881674" mass="0.5" diaginertia="0.0150001 0.015 0.00117991" />
          <joint name="backarmy_link_joint" pos="0 0 0" axis="0 1 0" range="-3.14 3.14" damping="10" stiffness="200" />
          <body name="backarm_link.002">
            <inertial pos="0.00129 0.00015 0.32583" quat="0.471858 -0.00115011 0.00061552 0.881674" mass="0.5" diaginertia="0.0150001 0.015 0.00117991" />
            <joint name="backarmz_link_joint" pos="0 0 0" axis="0 0 1" range="-3.14 3.14" damping="10" stiffness="200" />
            <geom name="backarm_collision" pos="0.00024 0.00103 0.33362" quat="0.707105 0.707108 0 0" type="mesh" mesh="backarm" contype="1" conaffinity="0" density="0" group="1" class="visualgeom" />
            <geom type="mesh" rgba="" mesh="backarm" pos="0.00024 0.00103 0.33362" quat="0.707105 0.707108 0 0" />
            <body name="forearm_link" pos="0 0 0.61707">
              <inertial pos="0.00038 0.00023 0.31921" quat="0.615412 -0.00116648 0.000910761 0.788205" mass="0.5" diaginertia="0.0151101 0.01511 0.00117988" />
              <joint name="forearmx_link_joint" pos="0 0 0" axis="-1 0 0" range="-3.14 3.14" damping="10" stiffness="200" />
              <geom name="forearm_collision" pos="-0.00061 0.00121 0.32742" quat="0.707105 0.707108 0 0" type="mesh" mesh="forearm" contype="1" conaffinity="0" density="0" group="1" class="visualgeom" />
              <geom type="mesh" rgba="" mesh="forearm" pos="-0.00061 0.00121 0.32742" quat="0.707105 0.707108 0 0" />
              <body name="palm_link" pos="0 0 0.61571">
                <inertial pos="-0.00568 -0.00267 0.14686" quat="0.704791 -0.0987436 -0.108121 0.694139" mass="0.2" diaginertia="0.00258044 0.00166819 0.00109138" />
                <joint name="ind0_link_joint" pos="0 0 0" axis="-1 0 0" range="-3.14 3.14" damping="10" stiffness="50" />
                <body name="palm_link.001">
                  <inertial pos="-0.00568 -0.00267 0.14686" quat="0.704791 -0.0987436 -0.108121 0.694139" mass="0.2" diaginertia="0.00258044 0.00166819 0.00109138" />
                  <joint name="ind01_link_joint" pos="0 0 0" axis="0 0 1" range="-3.14 3.14" damping="10" stiffness="50" />
                  <body name="palm_link.002">
                    <inertial pos="-0.00568 -0.00267 0.14686" quat="0.704791 -0.0987436 -0.108121 0.694139" mass="0.2" diaginertia="0.00258044 0.00166819 0.00109138" />
                    <joint name="ind02_link_joint" pos="0 0 0" axis="0 1 0" range="-3.14 3.14" damping="10" stiffness="50" />
                    <geom name="palm_collision" pos="-0.00958 -0.00222 0.14685" quat="0.707105 0.707108 0 0" type="mesh" mesh="palm" contype="1" conaffinity="0" density="0" group="1" class="visualgeom" />
                    <geom type="mesh" rgba="" mesh="palm" pos="-0.00958 -0.00222 0.14685" quat="0.707105 0.707108 0 0" />
                    <body name="ind0_link" pos="-0.06628 -0.00526 0.2478">
                      <inertial pos="0.00628 -0.00214 0.05481" quat="0.625708 0.0423807 0.00175499 0.778903" mass="0.2" diaginertia="0.000651964 0.000642289 5.5747e-05" />
                      <joint name="ind0i_link_joint" pos="0 0 0" axis="-1 0 0" range="-3.14 3.14" damping="10" stiffness="200" />
                      <geom name="ind0_collision" pos="0.00688 -0.00351 0.07148" quat="0.707105 0.707108 0 0" type="mesh" mesh="indo0" contype="1" conaffinity="0" density="0" group="1" class="visualgeom" />
                      <geom type="mesh" rgba="" mesh="indo0" pos="0.00688 -0.00351 0.07148" quat="0.707105 0.707108 0 0" />
                      <body name="ind1_link" pos="0.00737 -0.00269 0.10775">
                        <inertial pos="5e-05 -0.00086 0.02902" quat="0.707107 0 0 0.707107" mass="0.2" diaginertia="0.00016 0.00014 4e-05" />
                        <joint name="ind1_link_joint" pos="0 0 0" axis="-1 0 0" range="-3.14 3.14" damping="10" stiffness="200" />
                        <geom name="ind1_collision" pos="-0.00022 -0.00015 0.03627" quat="0.707105 0.707108 0 0" type="mesh" mesh="ind1" contype="1" conaffinity="0" density="0" group="1" class="visualgeom" />
                        <geom type="mesh" rgba="" mesh="ind1" pos="-0.00022 -0.00015 0.03627" quat="0.707105 0.707108 0 0" />
                        <body name="ind2_link" pos="-8e-05 0.00019 0.05358">
                          <inertial pos="0.00013 -0.00141 0.02231" quat="0.70605 0.0386363 -0.0386363 0.70605" mass="0.2" diaginertia="0.000121098 0.00011 2.89023e-05" />
                          <joint name="ind2_link_joint" pos="0 0 0" axis="-1 0 0" range="-3.14 3.14" damping="10" stiffness="200" />
                          <geom name="ind2_collision" pos="0.00044 0.00109 0.01686" quat="0.707105 0.707108 0 0" type="mesh" mesh="ind2" contype="1" conaffinity="0" density="0" group="1" class="visualgeom" />
                          <geom type="mesh" rgba="" mesh="ind2" pos="0.00044 0.00109 0.01686" quat="0.707105 0.707108 0 0" />
                        </body>
                      </body>
                    </body>
                    <body name="mid0_link" pos="-0.02463 -0.00511 0.24156">
                      <inertial pos="0.00614 -0.0015 0.06417" quat="0.634805 0.0378977 0.00197693 0.77174" mass="0.2" diaginertia="0.000721714 0.000712089 5.6197e-05" />
                      <joint name="mid0_link_joint" pos="0 0 0" axis="-1 0 0" range="-3.14 3.14" damping="10" stiffness="200" />
                      <geom name="mid0_collision" pos="0.00653 -0.00358 0.07529" quat="0.707105 0.707108 0 0" type="mesh" mesh="mid0" contype="1" conaffinity="0" density="0" group="1" class="visualgeom" />
                      <geom type="mesh" rgba="" mesh="mid0" pos="0.00653 -0.00358 0.07529" quat="0.707105 0.707108 0 0" />
                      <body name="mid1_link" pos="0.00662 -0.00299 0.11437">
                        <inertial pos="0.00016 -0.0007 0.03234" quat="0.707107 0 0 0.707107" mass="0.2" diaginertia="0.00021 0.0002 4e-05" />
                        <joint name="mid1_link_joint" pos="0 0 0" axis="-1 0 0" range="-3.14 3.14" damping="10" stiffness="200" />
                        <geom name="mid1_collision" pos="-2e-05 -5e-05 0.0423" quat="0.707105 0.707108 0 0" type="mesh" mesh="mid1" contype="1" conaffinity="0" density="0" group="1" class="visualgeom" />
                        <geom type="mesh" rgba="" mesh="mid1" pos="-2e-05 -5e-05 0.0423" quat="0.707105 0.707108 0 0" />
                        <body name="mid2_link" pos="-0.00018 0.00014 0.06014">
                          <inertial pos="0.00033 -0.00121 0.02238" quat="0.70605 0.0386363 -0.0386363 0.70605" mass="0.2" diaginertia="0.000121098 0.00011 2.89023e-05" />
                          <joint name="mid2_link_joint" pos="0 0 0" axis="-1 0 0" range="-3.14 3.14" damping="10" stiffness="200" />
                          <geom name="mid2_collision" pos="0.00064 0.00128 0.01692" quat="0.707105 0.707108 0 0" type="mesh" mesh="mid2" contype="1" conaffinity="0" density="0" group="1" class="visualgeom" />
                          <geom type="mesh" rgba="" mesh="mid2" pos="0.00064 0.00128 0.01692" quat="0.707105 0.707108 0 0" />
                        </body>
                      </body>
                    </body>
                    <body name="pink0_link" pos="0.05707 -0.00491 0.21334">
                      <inertial pos="0.00601 -0.00221 0.05038" quat="0.673765 0.0428667 -0.00107238 0.7377" mass="0.2" diaginertia="0.000561952 0.000541695 5.63522e-05" />
                      <joint name="pink0_link_joint" pos="0 0 0" axis="-1 0 0" range="-3.14 3.14" damping="10" stiffness="200" />
                      <geom name="pink0_collision" pos="0.0064 -0.00332 0.06525" quat="0.707105 0.707108 0 0" type="mesh" mesh="pink0" contype="1" conaffinity="0" density="0" group="1" class="visualgeom" />
                      <geom type="mesh" rgba="" mesh="pink0" pos="0.0064 -0.00332 0.06525" quat="0.707105 0.707108 0 0" />
                      <body name="pink1_link" pos="0.00763 -0.00303 0.09828">
                        <inertial pos="-0.00051 -0.00028 0.02895" quat="0.707107 0 0 0.707107" mass="0.2" diaginertia="0.00013 0.00012 4e-05" />
                        <joint name="pink1_link_joint" pos="0 0 0" axis="-1 0 0" range="-3.14 3.14" damping="10" stiffness="200" />
                        <geom name="pink1_collision" pos="-0.00074 -0.00025 0.03199" quat="0.707105 0.707108 0 0" type="mesh" mesh="pink1" contype="1" conaffinity="0" density="0" group="1" class="visualgeom" />
                        <geom type="mesh" rgba="" mesh="pink1" pos="-0.00074 -0.00025 0.03199" quat="0.707105 0.707108 0 0" />
                        <body name="pink2_link" pos="-0.00065 -1e-05 0.04655">
                          <inertial pos="0.0001 -0.00121 0.02227" quat="0.70605 0.0386363 -0.0386363 0.70605" mass="0.2" diaginertia="0.000121098 0.00011 2.89023e-05" />
                          <joint name="pink2_link_joint" pos="0 0 0" axis="-1 0 0" range="-3.14 3.14" damping="10" stiffness="200" />
                          <geom name="pink2_collision" pos="0.00041 0.00128 0.01682" quat="0.707105 0.707108 0 0" type="mesh" mesh="pink2" contype="1" conaffinity="0" density="0" group="1" class="visualgeom" />
                          <geom type="mesh" rgba="" mesh="pink2" pos="0.00041 0.00128 0.01682" quat="0.707105 0.707108 0 0" />
                        </body>
                      </body>
                    </body>
                    <body name="ring0_link" pos="0.01624 -0.0036 0.22594">
                      <inertial pos="0.00587 -0.00375 0.05912" quat="0.671841 0.0381025 0.0041495 0.739703" mass="0.2" diaginertia="0.000721533 0.000702308 5.61592e-05" />
                      <joint name="ring0_link_joint" pos="0 0 0" axis="-1 0 0" range="-3.14 3.14" damping="10" stiffness="200" />
                      <geom name="ring0_collision" pos="0.00634 -0.00508 0.07588" quat="0.707105 0.707108 0 0" type="mesh" mesh="ring0" contype="1" conaffinity="0" density="0" group="1" class="visualgeom" />
                      <geom type="mesh" rgba="" mesh="ring0" pos="0.00634 -0.00508 0.07588" quat="0.707105 0.707108 0 0" />
                      <body name="ring1_link" pos="0.0068 -0.00436 0.11628">
                        <inertial pos="0.00011 -0.00083 0.03179" quat="0.707107 0 0 0.707107" mass="0.2" diaginertia="0.00021 0.0002 4e-05" />
                        <joint name="ring1_link_joint" pos="0 0 0" axis="-1 0 0" range="-3.14 3.14" damping="10" stiffness="200" />
                        <geom name="ring1_collision" pos="-5e-05 -0.00019 0.04175" quat="0.707105 0.707108 0 0" type="mesh" mesh="ring1" contype="1" conaffinity="0" density="0" group="1" class="visualgeom" />
                        <geom type="mesh" rgba="" mesh="ring1" pos="-5e-05 -0.00019 0.04175" quat="0.707105 0.707108 0 0" />
                        <body name="ring2_link" pos="-0.00012 -3e-05 0.05997">
                          <inertial pos="0.00022 -0.00117 0.02224" quat="0.70605 0.0386363 -0.0386363 0.70605" mass="0.2" diaginertia="0.000121098 0.00011 2.89023e-05" />
                          <joint name="ring2_link_joint" pos="0 0 0" axis="-1 0 0" range="-3.14 3.14" damping="10" stiffness="200" />
                          <geom name="ring2_collision" pos="0.00053 0.00132 0.01679" quat="0.707105 0.707108 0 0" type="mesh" mesh="ring2" contype="1" conaffinity="0" density="0" group="1" class="visualgeom" />
                          <geom type="mesh" rgba="" mesh="ring2" pos="0.00053 0.00132 0.01679" quat="0.707105 0.707108 0 0" />
                        </body>
                      </body>
                    </body>
                    <body name="thumb0_link" pos="-0.08268 -0.01129 0.11191">
                      <inertial pos="-0.01535 1e-05 -0.01547" quat="0.92388 0 0.382683 0" mass="0.2" diaginertia="7e-05 5e-05 5e-05" />
                      <joint name="thumb0_link_joint" pos="0 0 0" axis="-0.681442 0 -0.731872" range="-3.14 3.14" damping="10" stiffness="200" />
                      <geom name="thumb_joint_collision" pos="-0.01585 1e-05 -0.01618" quat="0.707105 0.707108 0 0" type="mesh" mesh="thumb_joint" contype="1" conaffinity="0" density="0" group="1" class="visualgeom" />
                      <geom type="mesh" rgba="" mesh="thumb_joint" pos="-0.01585 1e-05 -0.01618" quat="0.707105 0.707108 0 0" />
                      <body name="thumb1_link" pos="-0.01952 -0.00025 -0.01952">
                        <inertial pos="-0.02584 0.00336 0.03316" quat="0.941373 -0.0432974 -0.333222 0.0300876" mass="0.2" diaginertia="0.000585402 0.000551484 9.31143e-05" />
                        <joint name="thumb1_link_joint" pos="0 0 0" axis="0.0419599 0.999119 0.00118" range="-3.14 3.14" damping="10" stiffness="200" />
                        <geom name="thumb0_collision" pos="-0.02431 0.00336 0.03351" quat="0.670756 0.741544 0.00840695 0.0113736" type="mesh" mesh="thumb0" contype="1" conaffinity="0" density="0" group="1" class="visualgeom" />
                        <geom type="mesh" rgba="" mesh="thumb0" pos="-0.02431 0.00336 0.03351" quat="0.670756 0.741544 0.00840695 0.0113736" />
                        <body name="thumb2_link" pos="-0.05553 0.00533 0.072" quat="0.998646 0.0500528 -0.00209774 0.0139869">
                          <inertial pos="-0.02365 0.00718 0.03315" quat="0.950625 -0.0926997 -0.295286 0.0228939" mass="0.2" diaginertia="0.000394932 0.000378074 6.69931e-05" />
                          <joint name="thumb2_link_joint" pos="0 0 0" axis="0.135841 0.984355 -0.112221" range="-3.14 3.14" damping="10" stiffness="200" />
                          <geom name="thumb1_collision" pos="-0.03251 0.0107 0.04591" quat="0.711311 0.702794 0.00940002 0.00545161" type="mesh" mesh="thumb1" contype="1" conaffinity="0" density="0" group="1" class="visualgeom" />
                          <geom type="mesh" rgba="" mesh="thumb1" pos="-0.03251 0.0107 0.04591" quat="0.711311 0.702794 0.00940002 0.00545161" />
                          <body name="thumb3_link" pos="-0.04382 0.01172 0.06431">
                            <inertial pos="-0.01671 0.00511 0.02337" quat="0.933903 -0.13946 -0.318592 0.0829195" mass="0.2" diaginertia="0.000197339 0.000185221 4.74402e-05" />
                            <joint name="thumb3_link_joint" pos="0 0 0" axis="0.135841 0.984355 -0.112221" range="-3.14 3.14" damping="10" stiffness="200" />
                            <geom name="thumb2_collision" pos="-0.01067 0.00396 0.02091" quat="0.750847 0.656885 -0.0607464 -0.0322599" type="mesh" mesh="thumb2" contype="1" conaffinity="0" density="0" group="1" class="visualgeom" />
                            <geom type="mesh" rgba="" mesh="thumb2" pos="-0.01067 0.00396 0.02091" quat="0.750847 0.656885 -0.0607464 -0.0322599" />
                          </body>
                        </body>
                      </body>
                    </body>
                  </body>
                </body>
              </body>
            </body>
          </body>
        </body>
      </body>
    </body>
  </worldbody>

  <actuator>
    <motor name="backarmx_link_joint" joint="backarmx_link_joint" ctrllimited="true" ctrlrange="-1 1" gear="600" />
    <motor name="backarmy_link_joint" joint="backarmy_link_joint" ctrllimited="true" ctrlrange="-1 1" gear="600" />
    <motor name="backarmz_link_joint" joint="backarmz_link_joint" ctrllimited="true" ctrlrange="-1 1" gear="600" />
    <motor name="forearmx_link_joint" joint="forearmx_link_joint" ctrllimited="true" ctrlrange="-1 1" gear="600" />
    <motor name="ind0_link_joint" joint="ind0_link_joint" ctrllimited="true" ctrlrange="-1 1" gear="600" />
    <motor name="ind01_link_joint" joint="ind01_link_joint" ctrllimited="true" ctrlrange="-1 1" gear="600" />
    <motor name="ind02_link_joint" joint="ind02_link_joint" ctrllimited="true" ctrlrange="-1 1" gear="600" />
    <motor name="ind0i_link_joint" joint="ind0i_link_joint" ctrllimited="true" ctrlrange="-1 1" gear="600" />
    <motor name="ind1_link_joint" joint="ind1_link_joint" ctrllimited="true" ctrlrange="-1 1" gear="600" />
    <motor name="ind2_link_joint" joint="ind2_link_joint" ctrllimited="true" ctrlrange="-1 1" gear="600" />
    <motor name="mid0_link_joint" joint="mid0_link_joint" ctrllimited="true" ctrlrange="-1 1" gear="600" />
    <motor name="mid1_link_joint" joint="mid1_link_joint" ctrllimited="true" ctrlrange="-1 1" gear="600" />
    <motor name="mid2_link_joint" joint="mid2_link_joint" ctrllimited="true" ctrlrange="-1 1" gear="600" />
    <motor name="pink0_link_joint" joint="pink0_link_joint" ctrllimited="true" ctrlrange="-1 1" gear="600" />
    <motor name="pink1_link_joint" joint="pink1_link_joint" ctrllimited="true" ctrlrange="-1 1" gear="600" />
    <motor name="pink2_link_joint" joint="pink2_link_joint" ctrllimited="true" ctrlrange="-1 1" gear="600" />
    <motor name="ring0_link_joint" joint="ring0_link_joint" ctrllimited="true" ctrlrange="-1 1" gear="600" />
    <motor name="ring1_link_joint" joint="ring1_link_joint" ctrllimited="true" ctrlrange="-1 1" gear="600" />
    <motor name="ring2_link_joint" joint="ring2_link_joint" ctrllimited="true" ctrlrange="-1 1" gear="600" />
    <motor name="thumb0_link_joint" joint="thumb0_link_joint" ctrllimited="true" ctrlrange="-1 1" gear="600" />
    <motor name="thumb1_link_joint" joint="thumb1_link_joint" ctrllimited="true" ctrlrange="-1 1" gear="600" />
    <motor name="thumb2_link_joint" joint="thumb2_link_joint" ctrllimited="true" ctrlrange="-1 1" gear="600" />
    <motor name="thumb3_link_joint" joint="thumb3_link_joint" ctrllimited="true" ctrlrange="-1 1" gear="600" />
  </actuator>

  <sensor>
    <actuatorpos name="backarmx_link_joint_p" actuator="backarmx_link_joint" />
    <actuatorvel name="backarmx_link_joint_v" actuator="backarmx_link_joint" />
    <actuatorfrc name="backarmx_link_joint_f" actuator="backarmx_link_joint" noise="0.001" />
    <actuatorpos name="backarmy_link_joint_p" actuator="backarmy_link_joint" />
    <actuatorvel name="backarmy_link_joint_v" actuator="backarmy_link_joint" />
    <actuatorfrc name="backarmy_link_joint_f" actuator="backarmy_link_joint" noise="0.001" />
    <actuatorpos name="backarmz_link_joint_p" actuator="backarmz_link_joint" />
    <actuatorvel name="backarmz_link_joint_v" actuator="backarmz_link_joint" />
    <actuatorfrc name="backarmz_link_joint_f" actuator="backarmz_link_joint" noise="0.001" />
    <actuatorpos name="forearmx_link_joint_p" actuator="forearmx_link_joint" />
    <actuatorvel name="forearmx_link_joint_v" actuator="forearmx_link_joint" />
    <actuatorfrc name="forearmx_link_joint_f" actuator="forearmx_link_joint" noise="0.001" />
    <actuatorpos name="ind0_link_joint_p" actuator="ind0_link_joint" />
    <actuatorvel name="ind0_link_joint_v" actuator="ind0_link_joint" />
    <actuatorfrc name="ind0_link_joint_f" actuator="ind0_link_joint" noise="0.001" />
    <actuatorpos name="ind01_link_joint_p" actuator="ind01_link_joint" />
    <actuatorvel name="ind01_link_joint_v" actuator="ind01_link_joint" />
    <actuatorfrc name="ind01_link_joint_f" actuator="ind01_link_joint" noise="0.001" />
    <actuatorpos name="ind02_link_joint_p" actuator="ind02_link_joint" />
    <actuatorvel name="ind02_link_joint_v" actuator="ind02_link_joint" />
    <actuatorfrc name="ind02_link_joint_f" actuator="ind02_link_joint" noise="0.001" />
    <actuatorpos name="ind0i_link_joint_p" actuator="ind0i_link_joint" />
    <actuatorvel name="ind0i_link_joint_v" actuator="ind0i_link_joint" />
    <actuatorfrc name="ind0i_link_joint_f" actuator="ind0i_link_joint" noise="0.001" />
    <actuatorpos name="ind1_link_joint_p" actuator="ind1_link_joint" />
    <actuatorvel name="ind1_link_joint_v" actuator="ind1_link_joint" />
    <actuatorfrc name="ind1_link_joint_f" actuator="ind1_link_joint" noise="0.001" />
    <actuatorpos name="ind2_link_joint_p" actuator="ind2_link_joint" />
    <actuatorvel name="ind2_link_joint_v" actuator="ind2_link_joint" />
    <actuatorfrc name="ind2_link_joint_f" actuator="ind2_link_joint" noise="0.001" />
    <actuatorpos name="mid0_link_joint_p" actuator="mid0_link_joint" />
    <actuatorvel name="mid0_link_joint_v" actuator="mid0_link_joint" />
    <actuatorfrc name="mid0_link_joint_f" actuator="mid0_link_joint" noise="0.001" />
    <actuatorpos name="mid1_link_joint_p" actuator="mid1_link_joint" />
    <actuatorvel name="mid1_link_joint_v" actuator="mid1_link_joint" />
    <actuatorfrc name="mid1_link_joint_f" actuator="mid1_link_joint" noise="0.001" />
    <actuatorpos name="mid2_link_joint_p" actuator="mid2_link_joint" />
    <actuatorvel name="mid2_link_joint_v" actuator="mid2_link_joint" />
    <actuatorfrc name="mid2_link_joint_f" actuator="mid2_link_joint" noise="0.001" />
    <actuatorpos name="pink0_link_joint_p" actuator="pink0_link_joint" />
    <actuatorvel name="pink0_link_joint_v" actuator="pink0_link_joint" />
    <actuatorfrc name="pink0_link_joint_f" actuator="pink0_link_joint" noise="0.001" />
    <actuatorpos name="pink1_link_joint_p" actuator="pink1_link_joint" />
    <actuatorvel name="pink1_link_joint_v" actuator="pink1_link_joint" />
    <actuatorfrc name="pink1_link_joint_f" actuator="pink1_link_joint" noise="0.001" />
    <actuatorpos name="pink2_link_joint_p" actuator="pink2_link_joint" />
    <actuatorvel name="pink2_link_joint_v" actuator="pink2_link_joint" />
    <actuatorfrc name="pink2_link_joint_f" actuator="pink2_link_joint" noise="0.001" />
    <actuatorpos name="ring0_link_joint_p" actuator="ring0_link_joint" />
    <actuatorvel name="ring0_link_joint_v" actuator="ring0_link_joint" />
    <actuatorfrc name="ring0_link_joint_f" actuator="ring0_link_joint" noise="0.001" />
    <actuatorpos name="ring1_link_joint_p" actuator="ring1_link_joint" />
    <actuatorvel name="ring1_link_joint_v" actuator="ring1_link_joint" />
    <actuatorfrc name="ring1_link_joint_f" actuator="ring1_link_joint" noise="0.001" />
    <actuatorpos name="ring2_link_joint_p" actuator="ring2_link_joint" />
    <actuatorvel name="ring2_link_joint_v" actuator="ring2_link_joint" />
    <actuatorfrc name="ring2_link_joint_f" actuator="ring2_link_joint" noise="0.001" />
    <actuatorpos name="thumb0_link_joint_p" actuator="thumb0_link_joint" />
    <actuatorvel name="thumb0_link_joint_v" actuator="thumb0_link_joint" />
    <actuatorfrc name="thumb0_link_joint_f" actuator="thumb0_link_joint" noise="0.001" />
    <actuatorpos name="thumb1_link_joint_p" actuator="thumb1_link_joint" />
    <actuatorvel name="thumb1_link_joint_v" actuator="thumb1_link_joint" />
    <actuatorfrc name="thumb1_link_joint_f" actuator="thumb1_link_joint" noise="0.001" />
    <actuatorpos name="thumb2_link_joint_p" actuator="thumb2_link_joint" />
    <actuatorvel name="thumb2_link_joint_v" actuator="thumb2_link_joint" />
    <actuatorfrc name="thumb2_link_joint_f" actuator="thumb2_link_joint" noise="0.001" />
    <actuatorpos name="thumb3_link_joint_p" actuator="thumb3_link_joint" />
    <actuatorvel name="thumb3_link_joint_v" actuator="thumb3_link_joint" />
    <actuatorfrc name="thumb3_link_joint_f" actuator="thumb3_link_joint" noise="0.001" />
    <framequat name="orientation" objtype="site" noise="0.001" objname="imu" />
    <gyro name="angular-velocity" site="imu" noise="0.005" cutoff="34.9" />
  </sensor>

  <worldbody>
    
    <!-- <body name="object" pos="0 -0.75 1" > -->
      <!-- <geom rgba="1 1 1 0" type="sphere" size="0.05 0.05 0.05" density="0.001" conaffinity="0"/> -->
      <!-- <geom rgba="1 1 1 1" type="cylinder" size="0.05 0.05 0.5" density="0.01" contype="1" conaffinity="0"/> -->
      <!-- <joint name="obj_slidey" type="slide" pos="0 0 0" axis="0 1 0" range="-10.3213 10.3" damping="0.5"/> -->
      <!-- <joint name="obj_slidex" type="slide" pos="0 0 0" axis="1 0 0" range="-10.3213 10.3" damping="0.5"/> -->
    <!-- </body> -->
    <body name="object" pos="0 1 0.25">
      <joint name="free_object" type="free"/>  <!-- Allows full movement -->
      <geom rgba="1 1 1 1" type="cylinder" size="0.05 0.05 0.5" mass="10" density="0.01" contype="1" conaffinity="0"/>
    </body>

    <body name="goal" pos="0.45 -0.05 1">
      <geom rgba="1 0 0 1" type="cylinder" size="0.08 0.001 0.1" density='0.00001' contype="0" conaffinity="0"/>
      <joint name="goal_slidey" type="slide" pos="0 0 0" axis="0 1 0" range="-10.3213 10.3" damping="0.5"/>
      <joint name="goal_slidex" type="slide" pos="0 0 0" axis="1 0 0" range="-10.3213 10.3" damping="0.5"/>
    </body>
</worldbody>

</mujoco>